Workbook

Sheet exerc
A1: NUMEXERC | B1: DESEXERC | C1: HORAINICIO | D1: ALTITRANS | E1: NUMSUBMAP1 | F1: NUMSUBMAP2 | G1: NUMSUBMAP3 | H1: NUMSUBMAP4 | I1: QNH | J1: LIMINFQNH | K1: LIMSUPQNH | L1: PENDQNH | M1: NUMFORMMET | N1: CONSOLES
A2: 1 | B2: TESTE 1 | C2: 0.375 | D2: 8000 | E2: 1 | F2: 2 | G2: 3 | H2: 4 | I2: 1013 | J2: 955 | K2: 1055 | L2: 0.1 | N2: 0102

Sheet acft-exerc
A1: EXERCICIO | B1: TRAF | C1: DESIG | D1: SSR | E1: INDICATIVO | F1: DEP | G1: ARR | H1: PROCED | I1: NIV | J1: VEL(IAS) | K1: PROA | L1: TIPO DE COORD(F/D) | M1: FIXO | N1: DIST(SE POLAR) | O1: RADIAL/GRAUS(SE POLAR) | P1: CampoD | Q1: PIL | R1: ATIV | S1: MSG | T1: TEMMSG | U1: RVSM | V1: RMK
A2: 1 | B2: 1 | C2: A320 | D2: 4444 | E2: TAM3720 | F2: SBRJ | G2: SBCF | H2: STAR RWY 16 SP | I2: 300 | J2: 300 | L2: F | M2: ANSEM | Q2: 1 | R2: 0

Sheet acft-exerc-SCRIPT
A1: EXERCICIO | B1: TRAF | C1: DESIG | D1: SSR | E1: INDICATIVO | F1: DEP | G1: ARR | H1: PROCED | I1: NIV | J1: VEL(IAS) | K1: PROA | L1: TIPO DE COORD(F/D) | M1: FIXO | N1: DIST(SE POLAR) | O1: RADIAL/GRAUS(SE POLAR) | P1: CampoD | Q1: PIL | R1: ATIV | S1: MSG | T1: TEMMSG | U1: RVSM | V1: RMK
A2: {='acft-exerc'!A2:G1000} -> 1 | B2: 1 | C2: A320 | D2: 4444 | E2: TAM3720 | F2: SBRJ | G2: SBCF | H2: =VLOOKUP('acft-exerc'!H2,'lista procedimentos'!A1:B1000,2, FALSE) -> TRJ0073 | I2: {='acft-exerc'!I2:L1000} -> 300 | J2: 300 | L2: F | M2: =ifna(VLOOKUP('acft-exerc'!$M2,FIX!$A$2:$D1000,4, false),"") -> 47 | N2: {='acft-exerc'!N2:V1000} | Q2: 1 | R2: 0
M3: =ifna(VLOOKUP('acft-exerc'!$M3,FIX!$A$2:$D1000,4, false),"")
M4: =ifna(VLOOKUP('acft-exerc'!$M4,FIX!$A$2:$D1000,4, false),"")
M5: =ifna(VLOOKUP('acft-exerc'!$M5,FIX!$A$2:$D1000,4, false),"")
M6: =ifna(VLOOKUP('acft-exerc'!$M6,FIX!$A$2:$D1000,4, false),"")
M7: =ifna(VLOOKUP('acft-exerc'!$M7,FIX!$A$2:$D1000,4, false),"")
M8: =ifna(VLOOKUP('acft-exerc'!$M8,FIX!$A$2:$D1000,4, false),"")
M9: =ifna(VLOOKUP('acft-exerc'!$M9,FIX!$A$2:$D1000,4, false),"")
M10: =ifna(VLOOKUP('acft-exerc'!$M10,FIX!$A$2:$D1000,4, false),"")
M11: =ifna(VLOOKUP('acft-exerc'!$M11,FIX!$A$2:$D1000,4, false),"")
M12: =ifna(VLOOKUP('acft-exerc'!$M12,FIX!$A$2:$D1000,4, false),"")
M13: =ifna(VLOOKUP('acft-exerc'!$M13,FIX!$A$2:$D1000,4, false),"")
M14: =ifna(VLOOKUP('acft-exerc'!$M14,FIX!$A$2:$D1000,4, false),"")
M15: =ifna(VLOOKUP('acft-exerc'!$M15,FIX!$A$2:$D1000,4, false),"")
M16: =ifna(VLOOKUP('acft-exerc'!$M16,FIX!$A$2:$D1000,4, false),"")
M17: =ifna(VLOOKUP('acft-exerc'!$M17,FIX!$A$2:$D1000,4, false),"")
M18: =ifna(VLOOKUP('acft-exerc'!$M18,FIX!$A$2:$D1000,4, false),"")
M19: =ifna(VLOOKUP('acft-exerc'!$M19,FIX!$A$2:$D1000,4, false),"")
M20: =ifna(VLOOKUP('acft-exerc'!$M20,FIX!$A$2:$D1000,4, false),"")
M21: =ifna(VLOOKUP('acft-exerc'!$M21,FIX!$A$2:$D1000,4, false),"")
M22: =ifna(VLOOKUP('acft-exerc'!$M22,FIX!$A$2:$D1000,4, false),"")
M23: =ifna(VLOOKUP('acft-exerc'!$M23,FIX!$A$2:$D1000,4, false),"")
M24: =ifna(VLOOKUP('acft-exerc'!$M24,FIX!$A$2:$D1000,4, false),"")
M25: =ifna(VLOOKUP('acft-exerc'!$M25,FIX!$A$2:$D1000,4, false),"")
M26: =ifna(VLOOKUP('acft-exerc'!$M26,FIX!$A$2:$D1000,4, false),"")
M27: =ifna(VLOOKUP('acft-exerc'!$M27,FIX!$A$2:$D1000,4, false),"")
M28: =ifna(VLOOKUP('acft-exerc'!$M28,FIX!$A$2:$D1000,4, false),"")
M29: =ifna(VLOOKUP('acft-exerc'!$M29,FIX!$A$2:$D1000,4, false),"")
M30: =ifna(VLOOKUP('acft-exerc'!$M30,FIX!$A$2:$D1000,4, false),"")
M31: =ifna(VLOOKUP('acft-exerc'!$M31,FIX!$A$2:$D1000,4, false),"")
M32: =ifna(VLOOKUP('acft-exerc'!$M32,FIX!$A$2:$D1000,4, false),"")
M33: =ifna(VLOOKUP('acft-exerc'!$M33,FIX!$A$2:$D1000,4, false),"")
M34: =ifna(VLOOKUP('acft-exerc'!$M34,FIX!$A$2:$D1000,4, false),"")
M35: =ifna(VLOOKUP('acft-exerc'!$M35,FIX!$A$2:$D1000,4, false),"")
M36: =ifna(VLOOKUP('acft-exerc'!$M36,FIX!$A$2:$D1000,4, false),"")
M37: =ifna(VLOOKUP('acft-exerc'!$M37,FIX!$A$2:$D1000,4, false),"")
M38: =ifna(VLOOKUP('acft-exerc'!$M38,FIX!$A$2:$D1000,4, false),"")
M39: =ifna(VLOOKUP('acft-exerc'!$M39,FIX!$A$2:$D1000,4, false),"")
M40: =ifna(VLOOKUP('acft-exerc'!$M40,FIX!$A$2:$D1000,4, false),"")
...

Sheet lista procedimentos
A1: =IFERROR(__xludf.DUMMYFUNCTION("QUERY({trj!B2:B1000, trj!D2:D1000; sub!B2:B1000, sub!E2:E1000},""where Col1 is not null"")"),"STAR RWY 16 SP") -> STAR RWY 16 SP | B1: =IFERROR(__xludf.DUMMYFUNCTION("""COMPUTED_VALUE"""),"TRJ0073") -> TRJ0073
A2: =IFERROR(__xludf.DUMMYFUNCTION("""COMPUTED_VALUE"""),"SID RWY 16 MIMIP") -> SID RWY 16 MIMIP | B2: =IFERROR(__xludf.DUMMYFUNCTION("""COMPUTED_VALUE"""),"SUB001") -> SUB001

Sheet trj
A1: NUMERO | B1: NOME | C1: STAR?(S/N) | D1: PIPITCHU
A2: 73 | B2: STAR RWY 16 SP | C2: S | D2: =IF(A2<>"",CONCATENATE("TRJ",TEXT($A2,"0000"),""),"") -> TRJ0073
D3: =IF(A3<>"",CONCATENATE("TRJ",TEXT($A3,"0000"),""),"")
D4: =IF(A4<>"",CONCATENATE("TRJ",TEXT($A4,"0000"),""),"")
D5: =IF(A5<>"",CONCATENATE("TRJ",TEXT($A5,"0000"),""),"")
D6: =IF(A6<>"",CONCATENATE("TRJ",TEXT($A6,"0000"),""),"")
D7: =IF(A7<>"",CONCATENATE("TRJ",TEXT($A7,"0000"),""),"")
D8: =IF(A8<>"",CONCATENATE("TRJ",TEXT($A8,"0000"),""),"")
D9: =IF(A9<>"",CONCATENATE("TRJ",TEXT($A9,"0000"),""),"")
D10: =IF(A10<>"",CONCATENATE("TRJ",TEXT($A10,"0000"),""),"")
D11: =IF(A11<>"",CONCATENATE("TRJ",TEXT($A11,"0000"),""),"")
D12: =IF(A12<>"",CONCATENATE("TRJ",TEXT($A12,"0000"),""),"")
D13: =IF(A13<>"",CONCATENATE("TRJ",TEXT($A13,"0000"),""),"")
D14: =IF(A14<>"",CONCATENATE("TRJ",TEXT($A14,"0000"),""),"")
... D695: =IF(A695<>"",CONCATENATE("TRJ",TEXT($A695,"0000"),""),"")

Sheet pts_traje
A1: TRJ | B1: Nro do Ponto | C1: Tipo Coord(F/D) | D1: FIXO | E1: DIST(SE POLAR) | F1: RADIAL/GRAUS(SE POLAR) | G1: CAMPO D | H1: ALTITUDE(FT) | I1: VELOCIDADE(IAS) | J1: PROCEDIMENTO QUE LIGA
A2: STAR RWY 16 SP | B2: 1 | C2: F | D2: KIBAP | H2: 22000 | I2: 270
A3: STAR RWY 16 SP | B3: 2 | C3: F | D3: 5LN15
A4: STAR RWY 16 SP | B4: 3 | C4: F | D4: CF119 | H4: 16000 | I4: 250
A5: STAR RWY 16 SP | B5: 4 | C5: F | D5: CF001
A6: STAR RWY 16 SP | B6: 5 | C6: F | D6: CF153 | H6: =+10000 -> 10000

Sheet pts_traje-SCRIPT
A1: TRJ | B1: Nro do Ponto | C1: Tipo Coord(F/D) | D1: FIXO | E1: DIST(SE POLAR) | F1: RADIAL/GRAUS(SE POLAR) | G1: CAMPO D | H1: ALTITUDE | I1: VELOCIDADE(TAS) | J1: PROCEDIMENTO QUE LIGA
A2: =IFNA(right(VLOOKUP(pts_traje!$A2,trj!$B$2:$D1000,3,FALSE),4),"") -> 0073 | B2: {=pts_traje!B2:C1000} -> 1 | C2: F | D2: =IFNA(VLOOKUP(pts_traje!$D2,FIX!$A$2:$D1000,4,FALSE),"") -> 178 | E2: {=pts_traje!E2:H1000} | H2: 22000 | I2: =IF(pts_traje!$I2<>0,(ROUND(pts_traje!$I2+(pts_traje!$I2*0.02*pts_traje!$H2/1000),0)),"") -> 389 | J2: {=pts_traje!J2:J1000}
A3: =IFNA(right(VLOOKUP(pts_traje!$A3,trj!$B$2:$D1000,3,FALSE),4),"") -> 0073 | B3: 2 | C3: F | D3: =IFNA(VLOOKUP(pts_traje!$D3,FIX!$A$2:$D1000,4,FALSE),"") -> 15 | I3: =IF(pts_traje!$I3<>0,(ROUND(pts_traje!$I3+(pts_traje!$I3*0.02*pts_traje!$H3/1000),0)),"")
A4: =IFNA(right(VLOOKUP(pts_traje!$A4,trj!$B$2:$D1000,3,FALSE),4),"") -> 0073 | B4: 3 | C4: F | D4: =IFNA(VLOOKUP(pts_traje!$D4,FIX!$A$2:$D1000,4,FALSE),"") -> 131 | H4: 16000 | I4: =IF(pts_traje!$I4<>0,(ROUND(pts_traje!$I4+(pts_traje!$I4*0.02*pts_traje!$H4/1000),0)),"") -> 330
A5: =IFNA(right(VLOOKUP(pts_traje!$A5,trj!$B$2:$D1000,3,FALSE),4),"") -> 0073 | B5: 4 | C5: F | D5: =IFNA(VLOOKUP(pts_traje!$D5,FIX!$A$2:$D1000,4,FALSE),"") -> 101 | I5: =IF(pts_traje!$I5<>0,(ROUND(pts_traje!$I5+(pts_traje!$I5*0.02*pts_traje!$H5/1000),0)),"")
A6: =IFNA(right(VLOOKUP(pts_traje!$A6,trj!$B$2:$D1000,3,FALSE),4),"") -> 0073 | B6: 5 | C6: F | D6: =IFNA(VLOOKUP(pts_traje!$D6,FIX!$A$2:$D1000,4,FALSE),"") -> 152 | H6: 10000 | I6: =IF(pts_traje!$I6<>0,(ROUND(pts_traje!$I6+(pts_traje!$I6*0.02*pts_traje!$H6/1000),0)),"")
A7: =IFNA(right(VLOOKUP(pts_traje!$A7,trj!$B$2:$D1000,3,FALSE),4),"") | D7: =IFNA(VLOOKUP(pts_traje!$D7,FIX!$A$2:$D1000,4,FALSE),"") | I7: =IF(pts_traje!$I7<>0,(ROUND(pts_traje!$I7+(pts_traje!$I7*0.02*pts_traje!$H7/1000),0)),"")
A8: =IFNA(right(VLOOKUP(pts_traje!$A8,trj!$B$2:$D1000,3,FALSE),4),"") | D8: =IFNA(VLOOKUP(pts_traje!$D8,FIX!$A$2:$D1000,4,FALSE),"") | I8: =IF(pts_traje!$I8<>0,(ROUND(pts_traje!$I8+(pts_traje!$I8*0.02*pts_traje!$H8/1000),0)),"")
A9: =IFNA(right(VLOOKUP(pts_traje!$A9,trj!$B$2:$D1000,3,FALSE),4),"") | D9: =IFNA(VLOOKUP(pts_traje!$D9,FIX!$A$2:$D1000,4,FALSE),"") | I9: =IF(pts_traje!$I9<>0,(ROUND(pts_traje!$I9+(pts_traje!$I9*0.02*pts_traje!$H9/1000),0)),"")
A10: =IFNA(right(VLOOKUP(pts_traje!$A10,trj!$B$2:$D1000,3,FALSE),4),"") | D10: =IFNA(VLOOKUP(pts_traje!$D10,FIX!$A$2:$D1000,4,FALSE),"") | I10: =IF(pts_traje!$I10<>0,(ROUND(pts_traje!$I10+(pts_traje!$I10*0.02*pts_traje!$H10/1000),0)),"")
A11: =IFNA(right(VLOOKUP(pts_traje!$A11,trj!$B$2:$D1000,3,FALSE),4),"") | D11: =IFNA(VLOOKUP(pts_traje!$D11,FIX!$A$2:$D1000,4,FALSE),"") | I11: =IF(pts_traje!$I11<>0,(ROUND(pts_traje!$I11+(pts_traje!$I11*0.02*pts_traje!$H11/1000),0)),"")
A12: =IFNA(right(VLOOKUP(pts_traje!$A12,trj!$B$2:$D1000,3,FALSE),4),"") | D12: =IFNA(VLOOKUP(pts_traje!$D12,FIX!$A$2:$D1000,4,FALSE),"") | I12: =IF(pts_traje!$I12<>0,(ROUND(pts_traje!$I12+(pts_traje!$I12*0.02*pts_traje!$H12/1000),0)),"")
A13: =IFNA(right(VLOOKUP(pts_traje!$A13,trj!$B$2:$D1000,3,FALSE),4),"") | D13: =IFNA(VLOOKUP(pts_traje!$D13,FIX!$A$2:$D1000,4,FALSE),"") | I13: =IF(pts_traje!$I13<>0,(ROUND(pts_traje!$I13+(pts_traje!$I13*0.02*pts_traje!$H13/1000),0)),"")
A14: =IFNA(right(VLOOKUP(pts_traje!$A14,trj!$B$2:$D1000,3,FALSE),4),"") | D14: =IFNA(VLOOKUP(pts_traje!$D14,FIX!$A$2:$D1000,4,FALSE),"") | I14: =IF(pts_traje!$I14<>0,(ROUND(pts_traje!$I14+(pts_traje!$I14*0.02*pts_traje!$H14/1000),0)),"")
A15: =IFNA(right(VLOOKUP(pts_traje!$A15,trj!$B$2:$D1000,3,FALSE),4),"") | D15: =IFNA(VLOOKUP(pts_traje!$D15,FIX!$A$2:$D1000,4,FALSE),"") | I15: =IF(pts_traje!$I15<>0,(ROUND(pts_traje!$I15+(pts_traje!$I15*0.02*pts_traje!$H15/1000),0)),"")
A16: =IFNA(right(VLOOKUP(pts_traje!$A16,trj!$B$2:$D1000,3,FALSE),4),"") | D16: =IFNA(VLOOKUP(pts_traje!$D16,FIX!$A$2:$D1000,4,FALSE),"") | I16: =IF(pts_traje!$I16<>0,(ROUND(pts_traje!$I16+(pts_traje!$I16*0.02*pts_traje!$H16/1000),0)),"")
A17: =IFNA(right(VLOOKUP(pts_traje!$A17,trj!$B$2:$D1000,3,FALSE),4),"") | D17: =IFNA(VLOOKUP(pts_traje!$D17,FIX!$A$2:$D1000,4,FALSE),"") | I17: =IF(pts_traje!$I17<>0,(ROUND(pts_traje!$I17+(pts_traje!$I17*0.02*pts_traje!$H17/1000),0)),"")
A18: =IFNA(right(VLOOKUP(pts_traje!$A18,trj!$B$2:$D1000,3,FALSE),4),"") | D18: =IFNA(VLOOKUP(pts_traje!$D18,FIX!$A$2:$D1000,4,FALSE),"") | I18: =IF(pts_traje!$I18<>0,(ROUND(pts_traje!$I18+(pts_traje!$I18*0.02*pts_traje!$H18/1000),0)),"")
A19: =IFNA(right(VLOOKUP(pts_traje!$A19,trj!$B$2:$D1000,3,FALSE),4),"") | D19: =IFNA(VLOOKUP(pts_traje!$D19,FIX!$A$2:$D1000,4,FALSE),"") | I19: =IF(pts_traje!$I19<>0,(ROUND(pts_traje!$I19+(pts_traje!$I19*0.02*pts_traje!$H19/1000),0)),"")
A20: =IFNA(right(VLOOKUP(pts_traje!$A20,trj!$B$2:$D1000,3,FALSE),4),"") | D20: =IFNA(VLOOKUP(pts_traje!$D20,FIX!$A$2:$D1000,4,FALSE),"") | I20: =IF(pts_traje!$I20<>0,(ROUND(pts_traje!$I20+(pts_traje!$I20*0.02*pts_traje!$H20/1000),0)),"")
A21: =IFNA(right(VLOOKUP(pts_traje!$A21,trj!$B$2:$D1000,3,FALSE),4),"") | D21: =IFNA(VLOOKUP(pts_traje!$D21,FIX!$A$2:$D1000,4,FALSE),"") | I21: =IF(pts_traje!$I21<>0,(ROUND(pts_traje!$I21+(pts_traje!$I21*0.02*pts_traje!$H21/1000),0)),"")
A22: =IFNA(right(VLOOKUP(pts_traje!$A22,trj!$B$2:$D1000,3,FALSE),4),"") | D22: =IFNA(VLOOKUP(pts_traje!$D22,FIX!$A$2:$D1000,4,FALSE),"") | I22: =IF(pts_traje!$I22<>0,(ROUND(pts_traje!$I22+(pts_traje!$I22*0.02*pts_traje!$H22/1000),0)),"")
A23: =IFNA(right(VLOOKUP(pts_traje!$A23,trj!$B$2:$D1000,3,FALSE),4),"") | D23: =IFNA(VLOOKUP(pts_traje!$D23,FIX!$A$2:$D1000,4,FALSE),"") | I23: =IF(pts_traje!$I23<>0,(ROUND(pts_traje!$I23+(pts_traje!$I23*0.02*pts_traje!$H23/1000),0)),"")
A24: =IFNA(right(VLOOKUP(pts_traje!$A24,trj!$B$2:$D1000,3,FALSE),4),"") | D24: =IFNA(VLOOKUP(pts_traje!$D24,FIX!$A$2:$D1000,4,FALSE),"") | I24: =IF(pts_traje!$I24<>0,(ROUND(pts_traje!$I24+(pts_traje!$I24*0.02*pts_traje!$H24/1000),0)),"")
A25: =IFNA(right(VLOOKUP(pts_traje!$A25,trj!$B$2:$D1000,3,FALSE),4),"") | D25: =IFNA(VLOOKUP(pts_traje!$D25,FIX!$A$2:$D1000,4,FALSE),"") | I25: =IF(pts_traje!$I25<>0,(ROUND(pts_traje!$I25+(pts_traje!$I25*0.02*pts_traje!$H25/1000),0)),"")
A26: =IFNA(right(VLOOKUP(pts_traje!$A26,trj!$B$2:$D1000,3,FALSE),4),"") | D26: =IFNA(VLOOKUP(pts_traje!$D26,FIX!$A$2:$D1000,4,FALSE),"") | I26: =IF(pts_traje!$I26<>0,(ROUND(pts_traje!$I26+(pts_traje!$I26*0.02*pts_traje!$H26/1000),0)),"")
A27: =IFNA(right(VLOOKUP(pts_traje!$A27,trj!$B$2:$D1000,3,FALSE),4),"") | D27: =IFNA(VLOOKUP(pts_traje!$D27,FIX!$A$2:$D1000,4,FALSE),"") | I27: =IF(pts_traje!$I27<>0,(ROUND(pts_traje!$I27+(pts_traje!$I27*0.02*pts_traje!$H27/1000),0)),"")
A28: =IFNA(right(VLOOKUP(pts_traje!$A28,trj!$B$2:$D1000,3,FALSE),4),"") | D28: =IFNA(VLOOKUP(pts_traje!$D28,FIX!$A$2:$D1000,4,FALSE),"") | I28: =IF(pts_traje!$I28<>0,(ROUND(pts_traje!$I28+(pts_traje!$I28*0.02*pts_traje!$H28/1000),0)),"")
A29: =IFNA(right(VLOOKUP(pts_traje!$A29,trj!$B$2:$D1000,3,FALSE),4),"") | D29: =IFNA(VLOOKUP(pts_traje!$D29,FIX!$A$2:$D1000,4,FALSE),"") | I29: =IF(pts_traje!$I29<>0,(ROUND(pts_traje!$I29+(pts_traje!$I29*0.02*pts_traje!$H29/1000),0)),"")
A30: =IFNA(right(VLOOKUP(pts_traje!$A30,trj!$B$2:$D1000,3,FALSE),4),"") | D30: =IFNA(VLOOKUP(pts_traje!$D30,FIX!$A$2:$D1000,4,FALSE),"") | I30: =IF(pts_traje!$I30<>0,(ROUND(pts_traje!$I30+(pts_traje!$I30*0.02*pts_traje!$H30/1000),0)),"")
A31: =IFNA(right(VLOOKUP(pts_traje!$A31,trj!$B$2:$D1000,3,FALSE),4),"") | D31: =IFNA(VLOOKUP(pts_traje!$D31,FIX!$A$2:$D1000,4,FALSE),"") | I31: =IF(pts_traje!$I31<>0,(ROUND(pts_traje!$I31+(pts_traje!$I31*0.02*pts_traje!$H31/1000),0)),"")
A32: =IFNA(right(VLOOKUP(pts_traje!$A32,trj!$B$2:$D1000,3,FALSE),4),"") | D32: =IFNA(VLOOKUP(pts_traje!$D32,FIX!$A$2:$D1000,4,FALSE),"") | I32: =IF(pts_traje!$I32<>0,(ROUND(pts_traje!$I32+(pts_traje!$I32*0.02*pts_traje!$H32/1000),0)),"")
A33: =IFNA(right(VLOOKUP(pts_traje!$A33,trj!$B$2:$D1000,3,FALSE),4),"") | D33: =IFNA(VLOOKUP(pts_traje!$D33,FIX!$A$2:$D1000,4,FALSE),"") | I33: =IF(pts_traje!$I33<>0,(ROUND(pts_traje!$I33+(pts_traje!$I33*0.02*pts_traje!$H33/1000),0)),"")
A34: =IFNA(right(VLOOKUP(pts_traje!$A34,trj!$B$2:$D1000,3,FALSE),4),"") | D34: =IFNA(VLOOKUP(pts_traje!$D34,FIX!$A$2:$D1000,4,FALSE),"") | I34: =IF(pts_traje!$I34<>0,(ROUND(pts_traje!$I34+(pts_traje!$I34*0.02*pts_traje!$H34/1000),0)),"")
A35: =IFNA(right(VLOOKUP(pts_traje!$A35,trj!$B$2:$D1000,3,FALSE),4),"") | D35: =IFNA(VLOOKUP(pts_traje!$D35,FIX!$A$2:$D1000,4,FALSE),"") | I35: =IF(pts_traje!$I35<>0,(ROUND(pts_traje!$I35+(pts_traje!$I35*0.02*pts_traje!$H35/1000),0)),"")
A36: =IFNA(right(VLOOKUP(pts_traje!$A36,trj!$B$2:$D1000,3,FALSE),4),"") | D36: =IFNA(VLOOKUP(pts_traje!$D36,FIX!$A$2:$D1000,4,FALSE),"") | I36: =IF(pts_traje!$I36<>0,(ROUND(pts_traje!$I36+(pts_traje!$I36*0.02*pts_traje!$H36/1000),0)),"")
A37: =IFNA(right(VLOOKUP(pts_traje!$A37,trj!$B$2:$D1000,3,FALSE),4),"") | D37: =IFNA(VLOOKUP(pts_traje!$D37,FIX!$A$2:$D1000,4,FALSE),"") | I37: =IF(pts_traje!$I37<>0,(ROUND(pts_traje!$I37+(pts_traje!$I37*0.02*pts_traje!$H37/1000),0)),"")
A38: =IFNA(right(VLOOKUP(pts_traje!$A38,trj!$B$2:$D1000,3,FALSE),4),"") | D38: =IFNA(VLOOKUP(pts_traje!$D38,FIX!$A$2:$D1000,4,FALSE),"") | I38: =IF(pts_traje!$I38<>0,(ROUND(pts_traje!$I38+(pts_traje!$I38*0.02*pts_traje!$H38/1000),0)),"")
A39: =IFNA(right(VLOOKUP(pts_traje!$A39,trj!$B$2:$D1000,3,FALSE),4),"") | D39: =IFNA(VLOOKUP(pts_traje!$D39,FIX!$A$2:$D1000,4,FALSE),"") | I39: =IF(pts_traje!$I39<>0,(ROUND(pts_traje!$I39+(pts_traje!$I39*0.02*pts_traje!$H39/1000),0)),"")
A40: =IFNA(right(VLOOKUP(pts_traje!$A40,trj!$B$2:$D1000,3,FALSE),4),"") | D40: =IFNA(VLOOKUP(pts_traje!$D40,FIX!$A$2:$D1000,4,FALSE),"") | I40: =IF(pts_traje!$I40<>0,(ROUND(pts_traje!$I40+(pts_traje!$I40*0.02*pts_traje!$H40/1000),0)),"")
...

Sheet sub
A1: NUMERO | B1: NOME | C1: AERODROMO | D1: PISTA | E1: PIPITCHU
A2: 1 | B2: SID RWY 16 MIMIP | C2: SBCF | D2: 16 | E2: =IF($A2<>"",CONCATENATE("SUB",TEXT($A2,"000"),"")) -> SUB001
E3: =IFNA($A3,"")
E4: =IFNA($A4,"")
E5: =IFNA($A5,"")
E6: =IFNA($A6,"")
E7: =IFNA($A7,"")
E8: =IFNA($A8,"")
E9: =IFNA($A9,"")
E10: =IFNA($A10,"")
E11: =IFNA($A11,"")
E12: =IFNA($A12,"")
E13: =IFNA($A13,"")
E14: =IFNA($A14,"")
... E1000: =IFNA($A1000,"")

Sheet pts_sub
A1: SUB | B1: NRO PONTO | C1: TIPO COORD(F/D) | D1: FIXO | E1: DIST(SE POLAR) | F1: RADIAL/GRAUS(SE POLAR) | G1: CAMPO D | H1: ALTITUDE | I1: GRAD SUB | J1: VELOCIDADE(IAS) | K1: PROCEDIMENTO QUE LIGA
A2: SID RWY 16 MIMIP | B2: 1 | C2: D | D2: THR16 | E2: 3 | F2: 160 | H2: 3500 | I2: 8 | J2: 250
A3: SID RWY 16 MIMIP | B3: 2 | C3: F | D3: CF001 | H3: 6000 | I3: 8 | J3: 250
A4: SID RWY 16 MIMIP | B4: 3 | C4: F | D4: CF002 | H4: 8000 | I4: 8 | J4: 300
A5: SID RWY 16 MIMIP | B5: 4 | C5: F | D5: 5LN02 | H5: 9000 | I5: 8 | J5: 300
A6: SID RWY 16 MIMIP | B6: 5 | C6: F | D6: 5LN03 | H6: 12000 | I6: 8 | J6: 300
A7: SID RWY 16 MIMIP | B7: 6 | C7: F | D7: CF076 | H7: 14000 | I7: 8 | J7: 300
A8: SID RWY 16 MIMIP | B8: 7 | C8: F | D8: CF077 | H8: 40000 | I8: 8 | J8: 300
A9: SID RWY 16 MIMIP | B9: 8 | C9: F | D9: MIMIP | H9: 40000 | I9: 8 | J9: 300

Sheet pts_sub-SCRIPT
A1: SUB | B1: NRO PONTO | C1: TIPO COORD(F/D) | D1: FIXO | E1: DIST(SE POLAR) | F1: RADIAL/GRAUS(SE POLAR) | G1: CAMPO D | H1: ALTITUDE | I1: GRAD SUB | J1: VELOCIDADE(IAS) | K1: PROCEDIMENTO QUE LIGA
A2: =IFNA(VLOOKUP(pts_sub!$A2,sub!$B$2:$E1000,4,FALSE),"") -> SUB001 | B2: {=pts_sub!B2:C1000} -> 1 | C2: D | D2: =IFNA(VLOOKUP(pts_sub!$D2,FIX!$A$2:$D1000,4, FALSE),"") -> 222 | E2: {=pts_sub!E2:K1000} -> 3 | F2: 160 | H2: 3500 | I2: 8 | J2: 250
A3: =IFNA(VLOOKUP(pts_sub!$A3,sub!$B$2:$E1000,4,FALSE),"") -> SUB001 | B3: 2 | C3: F | D3: =IFNA(VLOOKUP(pts_sub!$D3,FIX!$A$2:$D1000,4, FALSE),"") -> 101 | H3: 6000 | I3: 8 | J3: 250
A4: =IFNA(VLOOKUP(pts_sub!$A4,sub!$B$2:$E1000,4,FALSE),"") -> SUB001 | B4: 3 | C4: F | D4: =IFNA(VLOOKUP(pts_sub!$D4,FIX!$A$2:$D1000,4, FALSE),"") -> 102 | H4: 8000 | I4: 8 | J4: 300
A5: =IFNA(VLOOKUP(pts_sub!$A5,sub!$B$2:$E1000,4,FALSE),"") -> SUB001 | B5: 4 | C5: F | D5: =IFNA(VLOOKUP(pts_sub!$D5,FIX!$A$2:$D1000,4, FALSE),"") -> 2 | H5: 9000 | I5: 8 | J5: 300
A6: =IFNA(VLOOKUP(pts_sub!$A6,sub!$B$2:$E1000,4,FALSE),"") -> SUB001 | B6: 5 | C6: F | D6: =IFNA(VLOOKUP(pts_sub!$D6,FIX!$A$2:$D1000,4, FALSE),"") -> 3 | H6: 12000 | I6: 8 | J6: 300
A7: =IFNA(VLOOKUP(pts_sub!$A7,sub!$B$2:$E1000,4,FALSE),"") -> SUB001 | B7: 6 | C7: F | D7: =IFNA(VLOOKUP(pts_sub!$D7,FIX!$A$2:$D1000,4, FALSE),"") -> 108 | H7: 14000 | I7: 8 | J7: 300
A8: =IFNA(VLOOKUP(pts_sub!$A8,sub!$B$2:$E1000,4,FALSE),"") -> SUB001 | B8: 7 | C8: F | D8: =IFNA(VLOOKUP(pts_sub!$D8,FIX!$A$2:$D1000,4, FALSE),"") -> 109 | H8: 40000 | I8: 8 | J8: 300
A9: =IFNA(VLOOKUP(pts_sub!$A9,sub!$B$2:$E1000,4,FALSE),"") -> SUB001 | B9: 8 | C9: F | D9: =IFNA(VLOOKUP(pts_sub!$D9,FIX!$A$2:$D1000,4, FALSE),"") -> 182 | H9: 40000 | I9: 8 | J9: 300
A10: =IFNA(VLOOKUP(pts_sub!$A10,sub!$B$2:$E1000,4,FALSE),"") | D10: =IFNA(VLOOKUP(pts_sub!$D10,FIX!$A$2:$D1000,4, FALSE),"")
A11: =IFNA(VLOOKUP(pts_sub!$A11,sub!$B$2:$E1000,4,FALSE),"") | D11: =IFNA(VLOOKUP(pts_sub!$D11,FIX!$A$2:$D1000,4, FALSE),"")
A12: =IFNA(VLOOKUP(pts_sub!$A12,sub!$B$2:$E1000,4,FALSE),"") | D12: =IFNA(VLOOKUP(pts_sub!$D12,FIX!$A$2:$D1000,4, FALSE),"")
A13: =IFNA(VLOOKUP(pts_sub!$A13,sub!$B$2:$E1000,4,FALSE),"") | D13: =IFNA(VLOOKUP(pts_sub!$D13,FIX!$A$2:$D1000,4, FALSE),"")
A14: =IFNA(VLOOKUP(pts_sub!$A14,sub!$B$2:$E1000,4,FALSE),"") | D14: =IFNA(VLOOKUP(pts_sub!$D14,FIX!$A$2:$D1000,4, FALSE),"")
A15: =IFNA(VLOOKUP(pts_sub!$A15,sub!$B$2:$E1000,4,FALSE),"") | D15: =IFNA(VLOOKUP(pts_sub!$D15,FIX!$A$2:$D1000,4, FALSE),"")
A16: =IFNA(VLOOKUP(pts_sub!$A16,sub!$B$2:$E1000,4,FALSE),"") | D16: =IFNA(VLOOKUP(pts_sub!$D16,FIX!$A$2:$D1000,4, FALSE),"")
A17: =IFNA(VLOOKUP(pts_sub!$A17,sub!$B$2:$E1000,4,FALSE),"") | D17: =IFNA(VLOOKUP(pts_sub!$D17,FIX!$A$2:$D1000,4, FALSE),"")
A18: =IFNA(VLOOKUP(pts_sub!$A18,sub!$B$2:$E1000,4,FALSE),"") | D18: =IFNA(VLOOKUP(pts_sub!$D18,FIX!$A$2:$D1000,4, FALSE),"")
A19: =IFNA(VLOOKUP(pts_sub!$A19,sub!$B$2:$E1000,4,FALSE),"") | D19: =IFNA(VLOOKUP(pts_sub!$D19,FIX!$A$2:$D1000,4, FALSE),"")
A20: =IFNA(VLOOKUP(pts_sub!$A20,sub!$B$2:$E1000,4,FALSE),"") | D20: =IFNA(VLOOKUP(pts_sub!$D20,FIX!$A$2:$D1000,4, FALSE),"")
A21: =IFNA(VLOOKUP(pts_sub!$A21,sub!$B$2:$E1000,4,FALSE),"") | D21: =IFNA(VLOOKUP(pts_sub!$D21,FIX!$A$2:$D1000,4, FALSE),"")
A22: =IFNA(VLOOKUP(pts_sub!$A22,sub!$B$2:$E1000,4,FALSE),"") | D22: =IFNA(VLOOKUP(pts_sub!$D22,FIX!$A$2:$D1000,4, FALSE),"")
A23: =IFNA(VLOOKUP(pts_sub!$A23,sub!$B$2:$E1000,4,FALSE),"") | D23: =IFNA(VLOOKUP(pts_sub!$D23,FIX!$A$2:$D1000,4, FALSE),"")
A24: =IFNA(VLOOKUP(pts_sub!$A24,sub!$B$2:$E1000,4,FALSE),"") | D24: =IFNA(VLOOKUP(pts_sub!$D24,FIX!$A$2:$D1000,4, FALSE),"")
A25: =IFNA(VLOOKUP(pts_sub!$A25,sub!$B$2:$E1000,4,FALSE),"") | D25: =IFNA(VLOOKUP(pts_sub!$D25,FIX!$A$2:$D1000,4, FALSE),"")
A26: =IFNA(VLOOKUP(pts_sub!$A26,sub!$B$2:$E1000,4,FALSE),"") | D26: =IFNA(VLOOKUP(pts_sub!$D26,FIX!$A$2:$D1000,4, FALSE),"")
A27: =IFNA(VLOOKUP(pts_sub!$A27,sub!$B$2:$E1000,4,FALSE),"") | D27: =IFNA(VLOOKUP(pts_sub!$D27,FIX!$A$2:$D1000,4, FALSE),"")
A28: =IFNA(VLOOKUP(pts_sub!$A28,sub!$B$2:$E1000,4,FALSE),"") | D28: =IFNA(VLOOKUP(pts_sub!$D28,FIX!$A$2:$D1000,4, FALSE),"")
A29: =IFNA(VLOOKUP(pts_sub!$A29,sub!$B$2:$E1000,4,FALSE),"") | D29: =IFNA(VLOOKUP(pts_sub!$D29,FIX!$A$2:$D1000,4, FALSE),"")
A30: =IFNA(VLOOKUP(pts_sub!$A30,sub!$B$2:$E1000,4,FALSE),"") | D30: =IFNA(VLOOKUP(pts_sub!$D30,FIX!$A$2:$D1000,4, FALSE),"")
A31: =IFNA(VLOOKUP(pts_sub!$A31,sub!$B$2:$E1000,4,FALSE),"") | D31: =IFNA(VLOOKUP(pts_sub!$D31,FIX!$A$2:$D1000,4, FALSE),"")
A32: =IFNA(VLOOKUP(pts_sub!$A32,sub!$B$2:$E1000,4,FALSE),"") | D32: =IFNA(VLOOKUP(pts_sub!$D32,FIX!$A$2:$D1000,4, FALSE),"")
A33: =IFNA(VLOOKUP(pts_sub!$A33,sub!$B$2:$E1000,4,FALSE),"") | D33: =IFNA(VLOOKUP(pts_sub!$D33,FIX!$A$2:$D1000,4, FALSE),"")
A34: =IFNA(VLOOKUP(pts_sub!$A34,sub!$B$2:$E1000,4,FALSE),"") | D34: =IFNA(VLOOKUP(pts_sub!$D34,FIX!$A$2:$D1000,4, FALSE),"")
A35: =IFNA(VLOOKUP(pts_sub!$A35,sub!$B$2:$E1000,4,FALSE),"") | D35: =IFNA(VLOOKUP(pts_sub!$D35,FIX!$A$2:$D1000,4, FALSE),"")
A36: =IFNA(VLOOKUP(pts_sub!$A36,sub!$B$2:$E1000,4,FALSE),"") | D36: =IFNA(VLOOKUP(pts_sub!$D36,FIX!$A$2:$D1000,4, FALSE),"")
A37: =IFNA(VLOOKUP(pts_sub!$A37,sub!$B$2:$E1000,4,FALSE),"") | D37: =IFNA(VLOOKUP(pts_sub!$D37,FIX!$A$2:$D1000,4, FALSE),"")
A38: =IFNA(VLOOKUP(pts_sub!$A38,sub!$B$2:$E1000,4,FALSE),"") | D38: =IFNA(VLOOKUP(pts_sub!$D38,FIX!$A$2:$D1000,4, FALSE),"")
A39: =IFNA(VLOOKUP(pts_sub!$A39,sub!$B$2:$E1000,4,FALSE),"") | D39: =IFNA(VLOOKUP(pts_sub!$D39,FIX!$A$2:$D1000,4, FALSE),"")
A40: =IFNA(VLOOKUP(pts_sub!$A40,sub!$B$2:$E1000,4,FALSE),"") | D40: =IFNA(VLOOKUP(pts_sub!$D40,FIX!$A$2:$D1000,4, FALSE),"")
...

Sheet FIX
A1: NOME | B1: LATITUDE(DMS) | C1: LONGITUDE(DMS) | D1: NUMERO DO FIXO | E1: LATITUDE(DMM) | F1: LONGITUDE(DMM)
A2: 5LN01 | B2: S19 55 15.03 | C2: W044 39 08.84 | D2: 1 | E2: =concatenate(RIGHT($G2,2),text($H2+$J2,"00.000"),LEFT($G2,1)) -> 1955.251S | F2: =concatenate(RIGHT($L2,3),text($M2+$O2,"00.000"),LEFT($L2,1)) -> 04439.147W | G2: =IFERROR(__xludf.DUMMYFUNCTION("SPLIT($B2,"" "")"),"S19") -> S19 | H2: =IFERROR(__xludf.DUMMYFUNCTION("""COMPUTED_VALUE"""),55.0) -> 55 | I2: =IFERROR(__xludf.DUMMYFUNCTION("""COMPUTED_VALUE"""),15.03) -> 15.03 | J2: =text(ROUND(I2/60,3),"0.000") -> 0.251 | L2: =IFERROR(__xludf.DUMMYFUNCTION("SPLIT($C2,"" "")"),"W044") -> W044 | M2: =IFERROR(__xludf.DUMMYFUNCTION("""COMPUTED_VALUE"""),39.0) -> 39 | N2: =IFERROR(__xludf.DUMMYFUNCTION("""COMPUTED_VALUE"""),8.84) -> 8.84 | O2: =text(round(N2/60,3),"0.000") -> 0.147 | Q2: =-1*(RIGHT(G2,2)+H2/60+INT(I2)/3600) -> -19.920833 | R2: =-1*(RIGHT(L2,3)+M2/60+int(N2)/3600) -> -44.652222
A3: 5LN02 | B3: S19 44 10.40 | C3: W044 13 36.38 | D3: 2 | E3: =concatenate(RIGHT($G3,2),text($H3+$J3,"00.000"),LEFT($G3,1)) -> 1944.173S | F3: =concatenate(RIGHT($L3,3),text($M3+$O3,"00.000"),LEFT($L3,1)) -> 04413.606W | G3: =IFERROR(__xludf.DUMMYFUNCTION("SPLIT($B3,"" "")"),"S19") -> S19 | H3: =IFERROR(__xludf.DUMMYFUNCTION("""COMPUTED_VALUE"""),44.0) -> 44 | I3: =IFERROR(__xludf.DUMMYFUNCTION("""COMPUTED_VALUE"""),10.4) -> 10.4 | J3: =text(ROUND(I3/60,3),"0.000") -> 0.173 | L3: =IFERROR(__xludf.DUMMYFUNCTION("SPLIT($C3,"" "")"),"W044") -> W044 | M3: =IFERROR(__xludf.DUMMYFUNCTION("""COMPUTED_VALUE"""),13.0) -> 13 | N3: =IFERROR(__xludf.DUMMYFUNCTION("""COMPUTED_VALUE"""),36.38) -> 36.38 | O3: =text(round(N3/60,3),"0.000") -> 0.606 | Q3: =-1*(RIGHT(G3,2)+H3/60+INT(I3)/3600) -> -19.736111 | R3: =-1*(RIGHT(L3,3)+M3/60+int(N3)/3600) -> -44.226667
A4: 5LN03 | B4: S19 44 32.37 | C4: W044 20 18.34 | D4: 3 | E4: =concatenate(RIGHT($G4,2),text($H4+$J4,"00.000"),LEFT($G4,1)) -> 1944.540S | F4: =concatenate(RIGHT($L4,3),text($M4+$O4,"00.000"),LEFT($L4,1)) -> 04420.306W | G4: =IFERROR(__xludf.DUMMYFUNCTION("SPLIT($B4,"" "")"),"S19") -> S19 | H4: =IFERROR(__xludf.DUMMYFUNCTION("""COMPUTED_VALUE"""),44.0) -> 44 | I4: =IFERROR(__xludf.DUMMYFUNCTION("""COMPUTED_VALUE"""),32.37) -> 32.37 | J4: =text(ROUND(I4/60,3),"0.000") -> 0.540 | L4: =IFERROR(__xludf.DUMMYFUNCTION("SPLIT($C4,"" "")"),"W044") -> W044 | M4: =IFERROR(__xludf.DUMMYFUNCTION("""COMPUTED_VALUE"""),20.0) -> 20 | N4: =IFERROR(__xludf.DUMMYFUNCTION("""COMPUTED_VALUE"""),18.34) -> 18.34 | O4: =text(round(N4/60,3),"0.000") -> 0.306 | Q4: =-1*(RIGHT(G4,2)+H4/60+INT(I4)/3600) -> -19.742222 | R4: =-1*(RIGHT(L4,3)+M4/60+int(N4)/3600) -> -44.338333
A5: 5LN04 | B5: S19 56 42.81 | C5: W043 42 09.79 | D5: 4 | E5: =concatenate(RIGHT($G5,2),text($H5+$J5,"00.000"),LEFT($G5,1)) -> 1956.714S | F5: =concatenate(RIGHT($L5,3),text($M5+$O5,"00.000"),LEFT($L5,1)) -> 04342.163W | G5: =IFERROR(__xludf.DUMMYFUNCTION("SPLIT($B5,"" "")"),"S19") -> S19 | H5: =IFERROR(__xludf.DUMMYFUNCTION("""COMPUTED_VALUE"""),56.0) -> 56 | I5: =IFERROR(__xludf.DUMMYFUNCTION("""COMPUTED_VALUE"""),42.81) -> 42.81 | J5: =text(ROUND(I5/60,3),"0.000") -> 0.714 | L5: =IFERROR(__xludf.DUMMYFUNCTION("SPLIT($C5,"" "")"),"W043") -> W043 | M5: =IFERROR(__xludf.DUMMYFUNCTION("""COMPUTED_VALUE"""),42.0) -> 42 | N5: =IFERROR(__xludf.DUMMYFUNCTION("""COMPUTED_VALUE"""),9.79) -> 9.79 | O5: =text(round(N5/60,3),"0.000") -> 0.163 | Q5: =-1*(RIGHT(G5,2)+H5/60+INT(I5)/3600) -> -19.945 | R5: =-1*(RIGHT(L5,3)+M5/60+int(N5)/3600) -> -43.7025
A6: 5LN05 | B6: S19 57 18.40 | C6: W043 30 50.60 | D6: 5 | E6: =concatenate(RIGHT($G6,2),text($H6+$J6,"00.000"),LEFT($G6,1)) -> 1957.307S | F6: =concatenate(RIGHT($L6,3),text($M6+$O6,"00.000"),LEFT($L6,1)) -> 04330.843W | G6: =IFERROR(__xludf.DUMMYFUNCTION("SPLIT($B6,"" "")"),"S19") -> S19 | H6: =IFERROR(__xludf.DUMMYFUNCTION("""COMPUTED_VALUE"""),57.0) -> 57 | I6: =IFERROR(__xludf.DUMMYFUNCTION("""COMPUTED_VALUE"""),18.4) -> 18.4 | J6: =text(ROUND(I6/60,3),"0.000") -> 0.307 | L6: =IFERROR(__xludf.DUMMYFUNCTION("SPLIT($C6,"" "")"),"W043") -> W043 | M6: =IFERROR(__xludf.DUMMYFUNCTION("""COMPUTED_VALUE"""),30.0) -> 30 | N6: =IFERROR(__xludf.DUMMYFUNCTION("""COMPUTED_VALUE"""),50.6) -> 50.6 | O6: =text(round(N6/60,3),"0.000") -> 0.843 | Q6: =-1*(RIGHT(G6,2)+H6/60+INT(I6)/3600) -> -19.955 | R6: =-1*(RIGHT(L6,3)+M6/60+int(N6)/3600) -> -43.513889
A7: 5LN06 | B7: S19 58 27.56 | C7: W043 08 07.27 | D7: 6 | E7: =concatenate(RIGHT($G7,2),text($H7+$J7,"00.000"),LEFT($G7,1)) -> 1958.459S | F7: =concatenate(RIGHT($L7,3),text($M7+$O7,"00.000"),LEFT($L7,1)) -> 04308.121W | G7: =IFERROR(__xludf.DUMMYFUNCTION("SPLIT($B7,"" "")"),"S19") -> S19 | H7: =IFERROR(__xludf.DUMMYFUNCTION("""COMPUTED_VALUE"""),58.0) -> 58 | I7: =IFERROR(__xludf.DUMMYFUNCTION("""COMPUTED_VALUE"""),27.56) -> 27.56 | J7: =text(ROUND(I7/60,3),"0.000") -> 0.459 | L7: =IFERROR(__xludf.DUMMYFUNCTION("SPLIT($C7,"" "")"),"W043") -> W043 | M7: =IFERROR(__xludf.DUMMYFUNCTION("""COMPUTED_VALUE"""),8.0) -> 8 | N7: =IFERROR(__xludf.DUMMYFUNCTION("""COMPUTED_VALUE"""),7.27) -> 7.27 | O7: =text(round(N7/60,3),"0.000") -> 0.121 | Q7: =-1*(RIGHT(G7,2)+H7/60+INT(I7)/3600) -> -19.974167 | R7: =-1*(RIGHT(L7,3)+M7/60+int(N7)/3600) -> -43.135278
A8: 5LN07 | B8: S20 01 06.50 | C8: W044 07 45.04 | D8: 7 | E8: =concatenate(RIGHT($G8,2),text($H8+$J8,"00.000"),LEFT($G8,1)) -> 2001.108S | F8: =concatenate(RIGHT($L8,3),text($M8+$O8,"00.000"),LEFT($L8,1)) -> 04407.751W | G8: =IFERROR(__xludf.DUMMYFUNCTION("SPLIT($B8,"" "")"),"S20") -> S20 | H8: =IFERROR(__xludf.DUMMYFUNCTION("""COMPUTED_VALUE"""),1.0) -> 1 | I8: =IFERROR(__xludf.DUMMYFUNCTION("""COMPUTED_VALUE"""),6.5) -> 6.5 | J8: =text(ROUND(I8/60,3),"0.000") -> 0.108 | L8: =IFERROR(__xludf.DUMMYFUNCTION("SPLIT($C8,"" "")"),"W044") -> W044 | M8: =IFERROR(__xludf.DUMMYFUNCTION("""COMPUTED_VALUE"""),7.0) -> 7 | N8: =IFERROR(__xludf.DUMMYFUNCTION("""COMPUTED_VALUE"""),45.04) -> 45.04 | O8: =text(round(N8/60,3),"0.000") -> 0.751 | Q8: =-1*(RIGHT(G8,2)+H8/60+INT(I8)/3600) -> -20.018333 | R8: =-1*(RIGHT(L8,3)+M8/60+int(N8)/3600) -> -44.129167
A9: 5LN08 | B9: S18 52 28.86 | C9: W043 58 28.48 | D9: 8 | E9: =concatenate(RIGHT($G9,2),text($H9+$J9,"00.000"),LEFT($G9,1)) -> 1852.481S | F9: =concatenate(RIGHT($L9,3),text($M9+$O9,"00.000"),LEFT($L9,1)) -> 04358.475W | G9: =IFERROR(__xludf.DUMMYFUNCTION("SPLIT($B9,"" "")"),"S18") -> S18 | H9: =IFERROR(__xludf.DUMMYFUNCTION("""COMPUTED_VALUE"""),52.0) -> 52 | I9: =IFERROR(__xludf.DUMMYFUNCTION("""COMPUTED_VALUE"""),28.86) -> 28.86 | J9: =text(ROUND(I9/60,3),"0.000") -> 0.481 | L9: =IFERROR(__xludf.DUMMYFUNCTION("SPLIT($C9,"" "")"),"W043") -> W043 | M9: =IFERROR(__xludf.DUMMYFUNCTION("""COMPUTED_VALUE"""),58.0) -> 58 | N9: =IFERROR(__xludf.DUMMYFUNCTION("""COMPUTED_VALUE"""),28.48) -> 28.48 | O9: =text(round(N9/60,3),"0.000") -> 0.475 | Q9: =-1*(RIGHT(G9,2)+H9/60+INT(I9)/3600) -> -18.874444 | R9: =-1*(RIGHT(L9,3)+M9/60+int(N9)/3600) -> -43.974444
A10: 5LN09 | B10: S19 57 15.62 | C10: W043 57 33.24 | D10: 9 | E10: =concatenate(RIGHT($G10,2),text($H10+$J10,"00.000"),LEFT($G10,1)) -> 1957.260S | F10: =concatenate(RIGHT($L10,3),text($M10+$O10,"00.000"),LEFT($L10,1)) -> 04357.554W | G10: =IFERROR(__xludf.DUMMYFUNCTION("SPLIT($B10,"" "")"),"S19") -> S19 | H10: =IFERROR(__xludf.DUMMYFUNCTION("""COMPUTED_VALUE"""),57.0) -> 57 | I10: =IFERROR(__xludf.DUMMYFUNCTION("""COMPUTED_VALUE"""),15.62) -> 15.62 | J10: =text(ROUND(I10/60,3),"0.000") -> 0.260 | L10: =IFERROR(__xludf.DUMMYFUNCTION("SPLIT($C10,"" "")"),"W043") -> W043 | M10: =IFERROR(__xludf.DUMMYFUNCTION("""COMPUTED_VALUE"""),57.0) -> 57 | N10: =IFERROR(__xludf.DUMMYFUNCTION("""COMPUTED_VALUE"""),33.24) -> 33.24 | O10: =text(round(N10/60,3),"0.000") -> 0.554 | Q10: =-1*(RIGHT(G10,2)+H10/60+INT(I10)/3600) -> -19.954167 | R10: =-1*(RIGHT(L10,3)+M10/60+int(N10)/3600) -> -43.959167
A11: 5LN10 | B11: S19 12 00.79 | C11: W043 19 13.79 | D11: 10 | E11: =concatenate(RIGHT($G11,2),text($H11+$J11,"00.000"),LEFT($G11,1)) -> 1912.013S | F11: =concatenate(RIGHT($L11,3),text($M11+$O11,"00.000"),LEFT($L11,1)) -> 04319.230W | G11: =IFERROR(__xludf.DUMMYFUNCTION("SPLIT($B11,"" "")"),"S19") -> S19 | H11: =IFERROR(__xludf.DUMMYFUNCTION("""COMPUTED_VALUE"""),12.0) -> 12 | I11: =IFERROR(__xludf.DUMMYFUNCTION("""COMPUTED_VALUE"""),0.79) -> 0.79 | J11: =text(ROUND(I11/60,3),"0.000") -> 0.013 | L11: =IFERROR(__xludf.DUMMYFUNCTION("SPLIT($C11,"" "")"),"W043") -> W043 | M11: =IFERROR(__xludf.DUMMYFUNCTION("""COMPUTED_VALUE"""),19.0) -> 19 | N11: =IFERROR(__xludf.DUMMYFUNCTION("""COMPUTED_VALUE"""),13.79) -> 13.79 | O11: =text(round(N11/60,3),"0.000") -> 0.230 | Q11: =-1*(RIGHT(G11,2)+H11/60+INT(I11)/3600) -> -19.2 | R11: =-1*(RIGHT(L11,3)+M11/60+int(N11)/3600) -> -43.320278
A12: 5LN11 | B12: S20 16 33.27 | C12: W043 47 27.08 | D12: 11 | E12: =concatenate(RIGHT($G12,2),text($H12+$J12,"00.000"),LEFT($G12,1)) -> 2016.555S | F12: =concatenate(RIGHT($L12,3),text($M12+$O12,"00.000"),LEFT($L12,1)) -> 04347.451W | G12: =IFERROR(__xludf.DUMMYFUNCTION("SPLIT($B12,"" "")"),"S20") -> S20 | H12: =IFERROR(__xludf.DUMMYFUNCTION("""COMPUTED_VALUE"""),16.0) -> 16 | I12: =IFERROR(__xludf.DUMMYFUNCTION("""COMPUTED_VALUE"""),33.27) -> 33.27 | J12: =text(ROUND(I12/60,3),"0.000") -> 0.555 | L12: =IFERROR(__xludf.DUMMYFUNCTION("SPLIT($C12,"" "")"),"W043") -> W043 | M12: =IFERROR(__xludf.DUMMYFUNCTION("""COMPUTED_VALUE"""),47.0) -> 47 | N12: =IFERROR(__xludf.DUMMYFUNCTION("""COMPUTED_VALUE"""),27.08) -> 27.08 | O12: =text(round(N12/60,3),"0.000") -> 0.451 | Q12: =-1*(RIGHT(G12,2)+H12/60+INT(I12)/3600) -> -20.275833 | R12: =-1*(RIGHT(L12,3)+M12/60+int(N12)/3600) -> -43.790833
A13: 5LN12 | B13: S20 22 06.13 | C13: W043 53 45.81 | D13: 12 | E13: =concatenate(RIGHT($G13,2),text($H13+$J13,"00.000"),LEFT($G13,1)) -> 2022.102S | F13: =concatenate(RIGHT($L13,3),text($M13+$O13,"00.000"),LEFT($L13,1)) -> 04353.764W | G13: =IFERROR(__xludf.DUMMYFUNCTION("SPLIT($B13,"" "")"),"S20") -> S20 | H13: =IFERROR(__xludf.DUMMYFUNCTION("""COMPUTED_VALUE"""),22.0) -> 22 | I13: =IFERROR(__xludf.DUMMYFUNCTION("""COMPUTED_VALUE"""),6.13) -> 6.13 | J13: =text(ROUND(I13/60,3),"0.000") -> 0.102 | L13: =IFERROR(__xludf.DUMMYFUNCTION("SPLIT($C13,"" "")"),"W043") -> W043 | M13: =IFERROR(__xludf.DUMMYFUNCTION("""COMPUTED_VALUE"""),53.0) -> 53 | N13: =IFERROR(__xludf.DUMMYFUNCTION("""COMPUTED_VALUE"""),45.81) -> 45.81 | O13: =text(round(N13/60,3),"0.000") -> 0.764 | Q13: =-1*(RIGHT(G13,2)+H13/60+INT(I13)/3600) -> -20.368333 | R13: =-1*(RIGHT(L13,3)+M13/60+int(N13)/3600) -> -43.895833
A14: 5LN13 | B14: S19 07 26.96 | C14: W043 49 59.65 | D14: 13 | E14: =concatenate(RIGHT($G14,2),text($H14+$J14,"00.000"),LEFT($G14,1)) -> 1907.449S | F14: =concatenate(RIGHT($L14,3),text($M14+$O14,"00.000"),LEFT($L14,1)) -> 04349.994W | G14: =IFERROR(__xludf.DUMMYFUNCTION("SPLIT($B14,"" "")"),"S19") -> S19 | H14: =IFERROR(__xludf.DUMMYFUNCTION("""COMPUTED_VALUE"""),7.0) -> 7 | I14: =IFERROR(__xludf.DUMMYFUNCTION("""COMPUTED_VALUE"""),26.96) -> 26.96 | J14: =text(ROUND(I14/60,3),"0.000") -> 0.449 | L14: =IFERROR(__xludf.DUMMYFUNCTION("SPLIT($C14,"" "")"),"W043") -> W043 | M14: =IFERROR(__xludf.DUMMYFUNCTION("""COMPUTED_VALUE"""),49.0) -> 49 | N14: =IFERROR(__xludf.DUMMYFUNCTION("""COMPUTED_VALUE"""),59.65) -> 59.65 | O14: =text(round(N14/60,3),"0.000") -> 0.994 | Q14: =-1*(RIGHT(G14,2)+H14/60+INT(I14)/3600) -> -19.123889 | R14: =-1*(RIGHT(L14,3)+M14/60+int(N14)/3600) -> -43.833056
A15: 5LN14 | B15: S19 51 20.84 | C15: W044 17 09.30 | D15: 14 | E15: =concatenate(RIGHT($G15,2),text($H15+$J15,"00.000"),LEFT($G15,1)) -> 1951.347S | F15: =concatenate(RIGHT($L15,3),text($M15+$O15,"00.000"),LEFT($L15,1)) -> 04417.155W | G15: =IFERROR(__xludf.DUMMYFUNCTION("SPLIT($B15,"" "")"),"S19") -> S19 | H15: =IFERROR(__xludf.DUMMYFUNCTION("""COMPUTED_VALUE"""),51.0) -> 51 | I15: =IFERROR(__xludf.DUMMYFUNCTION("""COMPUTED_VALUE"""),20.84) -> 20.84 | J15: =text(ROUND(I15/60,3),"0.000") -> 0.347 | L15: =IFERROR(__xludf.DUMMYFUNCTION("SPLIT($C15,"" "")"),"W044") -> W044 | M15: =IFERROR(__xludf.DUMMYFUNCTION("""COMPUTED_VALUE"""),17.0) -> 17 | N15: =IFERROR(__xludf.DUMMYFUNCTION("""COMPUTED_VALUE"""),9.3) -> 9.3 | O15: =text(round(N15/60,3),"0.000") -> 0.155 | Q15: =-1*(RIGHT(G15,2)+H15/60+INT(I15)/3600) -> -19.855556 | R15: =-1*(RIGHT(L15,3)+M15/60+int(N15)/3600) -> -44.285833
A16: 5LN15 | B16: S20 29 10.83 | C16: W044 20 07.08 | D16: 15 | E16: =concatenate(RIGHT($G16,2),text($H16+$J16,"00.000"),LEFT($G16,1)) -> 2029.181S | F16: =concatenate(RIGHT($L16,3),text($M16+$O16,"00.000"),LEFT($L16,1)) -> 04420.118W | G16: =IFERROR(__xludf.DUMMYFUNCTION("SPLIT($B16,"" "")"),"S20") -> S20 | H16: =IFERROR(__xludf.DUMMYFUNCTION("""COMPUTED_VALUE"""),29.0) -> 29 | I16: =IFERROR(__xludf.DUMMYFUNCTION("""COMPUTED_VALUE"""),10.83) -> 10.83 | J16: =text(ROUND(I16/60,3),"0.000") -> 0.181 | L16: =IFERROR(__xludf.DUMMYFUNCTION("SPLIT($C16,"" "")"),"W044") -> W044 | M16: =IFERROR(__xludf.DUMMYFUNCTION("""COMPUTED_VALUE"""),20.0) -> 20 | N16: =IFERROR(__xludf.DUMMYFUNCTION("""COMPUTED_VALUE"""),7.08) -> 7.08 | O16: =text(round(N16/60,3),"0.000") -> 0.118 | Q16: =-1*(RIGHT(G16,2)+H16/60+INT(I16)/3600) -> -20.486111 | R16: =-1*(RIGHT(L16,3)+M16/60+int(N16)/3600) -> -44.335278
A17: 5LN16 | B17: S20 11 39.52 | C17: W043 15 32.91 | D17: 16 | E17: =concatenate(RIGHT($G17,2),text($H17+$J17,"00.000"),LEFT($G17,1)) -> 2011.659S | F17: =concatenate(RIGHT($L17,3),text($M17+$O17,"00.000"),LEFT($L17,1)) -> 04315.549W | G17: =IFERROR(__xludf.DUMMYFUNCTION("SPLIT($B17,"" "")"),"S20") -> S20 | H17: =IFERROR(__xludf.DUMMYFUNCTION("""COMPUTED_VALUE"""),11.0) -> 11 | I17: =IFERROR(__xludf.DUMMYFUNCTION("""COMPUTED_VALUE"""),39.52) -> 39.52 | J17: =text(ROUND(I17/60,3),"0.000") -> 0.659 | L17: =IFERROR(__xludf.DUMMYFUNCTION("SPLIT($C17,"" "")"),"W043") -> W043 | M17: =IFERROR(__xludf.DUMMYFUNCTION("""COMPUTED_VALUE"""),15.0) -> 15 | N17: =IFERROR(__xludf.DUMMYFUNCTION("""COMPUTED_VALUE"""),32.91) -> 32.91 | O17: =text(round(N17/60,3),"0.000") -> 0.549 | Q17: =-1*(RIGHT(G17,2)+H17/60+INT(I17)/3600) -> -20.194167 | R17: =-1*(RIGHT(L17,3)+M17/60+int(N17)/3600) -> -43.258889
A18: 5LN17 | B18: S19 48 31.71 | C18: W044 07 54.66 | D18: 17 | E18: =concatenate(RIGHT($G18,2),text($H18+$J18,"00.000"),LEFT($G18,1)) -> 1948.529S | F18: =concatenate(RIGHT($L18,3),text($M18+$O18,"00.000"),LEFT($L18,1)) -> 04407.911W | G18: =IFERROR(__xludf.DUMMYFUNCTION("SPLIT($B18,"" "")"),"S19") -> S19 | H18: =IFERROR(__xludf.DUMMYFUNCTION("""COMPUTED_VALUE"""),48.0) -> 48 | I18: =IFERROR(__xludf.DUMMYFUNCTION("""COMPUTED_VALUE"""),31.71) -> 31.71 | J18: =text(ROUND(I18/60,3),"0.000") -> 0.529 | L18: =IFERROR(__xludf.DUMMYFUNCTION("SPLIT($C18,"" "")"),"W044") -> W044 | M18: =IFERROR(__xludf.DUMMYFUNCTION("""COMPUTED_VALUE"""),7.0) -> 7 | N18: =IFERROR(__xludf.DUMMYFUNCTION("""COMPUTED_VALUE"""),54.66) -> 54.66 | O18: =text(round(N18/60,3),"0.000") -> 0.911 | Q18: =-1*(RIGHT(G18,2)+H18/60+INT(I18)/3600) -> -19.808611 | R18: =-1*(RIGHT(L18,3)+M18/60+int(N18)/3600) -> -44.131667
A19: 5LN18 | B19: S20 03 53.99 | C19: W044 36 03.67 | D19: 18 | E19: =concatenate(RIGHT($G19,2),text($H19+$J19,"00.000"),LEFT($G19,1)) -> 2003.900S | F19: =concatenate(RIGHT($L19,3),text($M19+$O19,"00.000"),LEFT($L19,1)) -> 04436.061W | G19: =IFERROR(__xludf.DUMMYFUNCTION("SPLIT($B19,"" "")"),"S20") -> S20 | H19: =IFERROR(__xludf.DUMMYFUNCTION("""COMPUTED_VALUE"""),3.0) -> 3 | I19: =IFERROR(__xludf.DUMMYFUNCTION("""COMPUTED_VALUE"""),53.99) -> 53.99 | J19: =text(ROUND(I19/60,3),"0.000") -> 0.900 | L19: =IFERROR(__xludf.DUMMYFUNCTION("SPLIT($C19,"" "")"),"W044") -> W044 | M19: =IFERROR(__xludf.DUMMYFUNCTION("""COMPUTED_VALUE"""),36.0) -> 36 | N19: =IFERROR(__xludf.DUMMYFUNCTION("""COMPUTED_VALUE"""),3.67) -> 3.67 | O19: =text(round(N19/60,3),"0.000") -> 0.061 | Q19: =-1*(RIGHT(G19,2)+H19/60+INT(I19)/3600) -> -20.064722 | R19: =-1*(RIGHT(L19,3)+M19/60+int(N19)/3600) -> -44.600833
A20: 5LN19 | B20: S20 24 46.36 | C20: W044 26 07.78 | D20: 19 | E20: =concatenate(RIGHT($G20,2),text($H20+$J20,"00.000"),LEFT($G20,1)) -> 2024.773S | F20: =concatenate(RIGHT($L20,3),text($M20+$O20,"00.000"),LEFT($L20,1)) -> 04426.130W | G20: =IFERROR(__xludf.DUMMYFUNCTION("SPLIT($B20,"" "")"),"S20") -> S20 | H20: =IFERROR(__xludf.DUMMYFUNCTION("""COMPUTED_VALUE"""),24.0) -> 24 | I20: =IFERROR(__xludf.DUMMYFUNCTION("""COMPUTED_VALUE"""),46.36) -> 46.36 | J20: =text(ROUND(I20/60,3),"0.000") -> 0.773 | L20: =IFERROR(__xludf.DUMMYFUNCTION("SPLIT($C20,"" "")"),"W044") -> W044 | M20: =IFERROR(__xludf.DUMMYFUNCTION("""COMPUTED_VALUE"""),26.0) -> 26 | N20: =IFERROR(__xludf.DUMMYFUNCTION("""COMPUTED_VALUE"""),7.78) -> 7.78 | O20: =text(round(N20/60,3),"0.000") -> 0.130 | Q20: =-1*(RIGHT(G20,2)+H20/60+INT(I20)/3600) -> -20.412778 | R20: =-1*(RIGHT(L20,3)+M20/60+int(N20)/3600) -> -44.435278
A21: 5LN20 | B21: S19 36 15.31 | C21: W044 31 19.72 | D21: 20 | E21: =concatenate(RIGHT($G21,2),text($H21+$J21,"00.000"),LEFT($G21,1)) -> 1936.255S | F21: =concatenate(RIGHT($L21,3),text($M21+$O21,"00.000"),LEFT($L21,1)) -> 04431.329W | G21: =IFERROR(__xludf.DUMMYFUNCTION("SPLIT($B21,"" "")"),"S19") -> S19 | H21: =IFERROR(__xludf.DUMMYFUNCTION("""COMPUTED_VALUE"""),36.0) -> 36 | I21: =IFERROR(__xludf.DUMMYFUNCTION("""COMPUTED_VALUE"""),15.31) -> 15.31 | J21: =text(ROUND(I21/60,3),"0.000") -> 0.255 | L21: =IFERROR(__xludf.DUMMYFUNCTION("SPLIT($C21,"" "")"),"W044") -> W044 | M21: =IFERROR(__xludf.DUMMYFUNCTION("""COMPUTED_VALUE"""),31.0) -> 31 | N21: =IFERROR(__xludf.DUMMYFUNCTION("""COMPUTED_VALUE"""),19.72) -> 19.72 | O21: =text(round(N21/60,3),"0.000") -> 0.329 | Q21: =-1*(RIGHT(G21,2)+H21/60+INT(I21)/3600) -> -19.604167 | R21: =-1*(RIGHT(L21,3)+M21/60+int(N21)/3600) -> -44.521944
A22: 5LN21 | B22: S20 05 12.34 | C22: W043 56 21.62 | D22: 21 | E22: =concatenate(RIGHT($G22,2),text($H22+$J22,"00.000"),LEFT($G22,1)) -> 2005.206S | F22: =concatenate(RIGHT($L22,3),text($M22+$O22,"00.000"),LEFT($L22,1)) -> 04356.360W | G22: =IFERROR(__xludf.DUMMYFUNCTION("SPLIT($B22,"" "")"),"S20") -> S20 | H22: =IFERROR(__xludf.DUMMYFUNCTION("""COMPUTED_VALUE"""),5.0) -> 5 | I22: =IFERROR(__xludf.DUMMYFUNCTION("""COMPUTED_VALUE"""),12.34) -> 12.34 | J22: =text(ROUND(I22/60,3),"0.000") -> 0.206 | L22: =IFERROR(__xludf.DUMMYFUNCTION("SPLIT($C22,"" "")"),"W043") -> W043 | M22: =IFERROR(__xludf.DUMMYFUNCTION("""COMPUTED_VALUE"""),56.0) -> 56 | N22: =IFERROR(__xludf.DUMMYFUNCTION("""COMPUTED_VALUE"""),21.62) -> 21.62 | O22: =text(round(N22/60,3),"0.000") -> 0.360 | Q22: =-1*(RIGHT(G22,2)+H22/60+INT(I22)/3600) -> -20.086667 | R22: =-1*(RIGHT(L22,3)+M22/60+int(N22)/3600) -> -43.939167
A23: 5LN22 | B23: S19 33 26.30 | C23: W043 46 55.24 | D23: 22 | E23: =concatenate(RIGHT($G23,2),text($H23+$J23,"00.000"),LEFT($G23,1)) -> 1933.438S | F23: =concatenate(RIGHT($L23,3),text($M23+$O23,"00.000"),LEFT($L23,1)) -> 04346.921W | G23: =IFERROR(__xludf.DUMMYFUNCTION("SPLIT($B23,"" "")"),"S19") -> S19 | H23: =IFERROR(__xludf.DUMMYFUNCTION("""COMPUTED_VALUE"""),33.0) -> 33 | I23: =IFERROR(__xludf.DUMMYFUNCTION("""COMPUTED_VALUE"""),26.3) -> 26.3 | J23: =text(ROUND(I23/60,3),"0.000") -> 0.438 | L23: =IFERROR(__xludf.DUMMYFUNCTION("SPLIT($C23,"" "")"),"W043") -> W043 | M23: =IFERROR(__xludf.DUMMYFUNCTION("""COMPUTED_VALUE"""),46.0) -> 46 | N23: =IFERROR(__xludf.DUMMYFUNCTION("""COMPUTED_VALUE"""),55.24) -> 55.24 | O23: =text(round(N23/60,3),"0.000") -> 0.921 | Q23: =-1*(RIGHT(G23,2)+H23/60+INT(I23)/3600) -> -19.557222 | R23: =-1*(RIGHT(L23,3)+M23/60+int(N23)/3600) -> -43.781944
A24: 5LN23 | B24: S19 41 06.07 | C24: W044 44 10.44 | D24: 23 | E24: =concatenate(RIGHT($G24,2),text($H24+$J24,"00.000"),LEFT($G24,1)) -> 1941.101S | F24: =concatenate(RIGHT($L24,3),text($M24+$O24,"00.000"),LEFT($L24,1)) -> 04444.174W | G24: =IFERROR(__xludf.DUMMYFUNCTION("SPLIT($B24,"" "")"),"S19") -> S19 | H24: =IFERROR(__xludf.DUMMYFUNCTION("""COMPUTED_VALUE"""),41.0) -> 41 | I24: =IFERROR(__xludf.DUMMYFUNCTION("""COMPUTED_VALUE"""),6.07) -> 6.07 | J24: =text(ROUND(I24/60,3),"0.000") -> 0.101 | L24: =IFERROR(__xludf.DUMMYFUNCTION("SPLIT($C24,"" "")"),"W044") -> W044 | M24: =IFERROR(__xludf.DUMMYFUNCTION("""COMPUTED_VALUE"""),44.0) -> 44 | N24: =IFERROR(__xludf.DUMMYFUNCTION("""COMPUTED_VALUE"""),10.44) -> 10.44 | O24: =text(round(N24/60,3),"0.000") -> 0.174 | Q24: =-1*(RIGHT(G24,2)+H24/60+INT(I24)/3600) -> -19.685 | R24: =-1*(RIGHT(L24,3)+M24/60+int(N24)/3600) -> -44.736111
A25: 5LN25 | B25: S19 17 40.13 | C25: W044 13 19.80 | D25: 24 | E25: =concatenate(RIGHT($G25,2),text($H25+$J25,"00.000"),LEFT($G25,1)) -> 1917.669S | F25: =concatenate(RIGHT($L25,3),text($M25+$O25,"00.000"),LEFT($L25,1)) -> 04413.330W | G25: =IFERROR(__xludf.DUMMYFUNCTION("SPLIT($B25,"" "")"),"S19") -> S19 | H25: =IFERROR(__xludf.DUMMYFUNCTION("""COMPUTED_VALUE"""),17.0) -> 17 | I25: =IFERROR(__xludf.DUMMYFUNCTION("""COMPUTED_VALUE"""),40.13) -> 40.13 | J25: =text(ROUND(I25/60,3),"0.000") -> 0.669 | L25: =IFERROR(__xludf.DUMMYFUNCTION("SPLIT($C25,"" "")"),"W044") -> W044 | M25: =IFERROR(__xludf.DUMMYFUNCTION("""COMPUTED_VALUE"""),13.0) -> 13 | N25: =IFERROR(__xludf.DUMMYFUNCTION("""COMPUTED_VALUE"""),19.8) -> 19.8 | O25: =text(round(N25/60,3),"0.000") -> 0.330 | Q25: =-1*(RIGHT(G25,2)+H25/60+INT(I25)/3600) -> -19.294444 | R25: =-1*(RIGHT(L25,3)+M25/60+int(N25)/3600) -> -44.221944
A26: 5LN26 | B26: S19 44 13.44 | C26: W043 59 33.06 | D26: 25 | E26: =concatenate(RIGHT($G26,2),text($H26+$J26,"00.000"),LEFT($G26,1)) -> 1944.224S | F26: =concatenate(RIGHT($L26,3),text($M26+$O26,"00.000"),LEFT($L26,1)) -> 04359.551W | G26: =IFERROR(__xludf.DUMMYFUNCTION("SPLIT($B26,"" "")"),"S19") -> S19 | H26: =IFERROR(__xludf.DUMMYFUNCTION("""COMPUTED_VALUE"""),44.0) -> 44 | I26: =IFERROR(__xludf.DUMMYFUNCTION("""COMPUTED_VALUE"""),13.44) -> 13.44 | J26: =text(ROUND(I26/60,3),"0.000") -> 0.224 | L26: =IFERROR(__xludf.DUMMYFUNCTION("SPLIT($C26,"" "")"),"W043") -> W043 | M26: =IFERROR(__xludf.DUMMYFUNCTION("""COMPUTED_VALUE"""),59.0) -> 59 | N26: =IFERROR(__xludf.DUMMYFUNCTION("""COMPUTED_VALUE"""),33.06) -> 33.06 | O26: =text(round(N26/60,3),"0.000") -> 0.551 | Q26: =-1*(RIGHT(G26,2)+H26/60+INT(I26)/3600) -> -19.736944 | R26: =-1*(RIGHT(L26,3)+M26/60+int(N26)/3600) -> -43.9925
A27: 5LN27 | B27: S19 29 08.26 | C27: W043 53 10.91 | D27: 26 | E27: =concatenate(RIGHT($G27,2),text($H27+$J27,"00.000"),LEFT($G27,1)) -> 1929.138S | F27: =concatenate(RIGHT($L27,3),text($M27+$O27,"00.000"),LEFT($L27,1)) -> 04353.182W | G27: =IFERROR(__xludf.DUMMYFUNCTION("SPLIT($B27,"" "")"),"S19") -> S19 | H27: =IFERROR(__xludf.DUMMYFUNCTION("""COMPUTED_VALUE"""),29.0) -> 29 | I27: =IFERROR(__xludf.DUMMYFUNCTION("""COMPUTED_VALUE"""),8.26) -> 8.26 | J27: =text(ROUND(I27/60,3),"0.000") -> 0.138 | L27: =IFERROR(__xludf.DUMMYFUNCTION("SPLIT($C27,"" "")"),"W043") -> W043 | M27: =IFERROR(__xludf.DUMMYFUNCTION("""COMPUTED_VALUE"""),53.0) -> 53 | N27: =IFERROR(__xludf.DUMMYFUNCTION("""COMPUTED_VALUE"""),10.91) -> 10.91 | O27: =text(round(N27/60,3),"0.000") -> 0.182 | Q27: =-1*(RIGHT(G27,2)+H27/60+INT(I27)/3600) -> -19.485556 | R27: =-1*(RIGHT(L27,3)+M27/60+int(N27)/3600) -> -43.886111
A28: 5LN28 | B28: S20 04 12.06 | C28: W043 54 39.84 | D28: 27 | E28: =concatenate(RIGHT($G28,2),text($H28+$J28,"00.000"),LEFT($G28,1)) -> 2004.201S | F28: =concatenate(RIGHT($L28,3),text($M28+$O28,"00.000"),LEFT($L28,1)) -> 04354.664W | G28: =IFERROR(__xludf.DUMMYFUNCTION("SPLIT($B28,"" "")"),"S20") -> S20 | H28: =IFERROR(__xludf.DUMMYFUNCTION("""COMPUTED_VALUE"""),4.0) -> 4 | I28: =IFERROR(__xludf.DUMMYFUNCTION("""COMPUTED_VALUE"""),12.06) -> 12.06 | J28: =text(ROUND(I28/60,3),"0.000") -> 0.201 | L28: =IFERROR(__xludf.DUMMYFUNCTION("SPLIT($C28,"" "")"),"W043") -> W043 | M28: =IFERROR(__xludf.DUMMYFUNCTION("""COMPUTED_VALUE"""),54.0) -> 54 | N28: =IFERROR(__xludf.DUMMYFUNCTION("""COMPUTED_VALUE"""),39.84) -> 39.84 | O28: =text(round(N28/60,3),"0.000") -> 0.664 | Q28: =-1*(RIGHT(G28,2)+H28/60+INT(I28)/3600) -> -20.07 | R28: =-1*(RIGHT(L28,3)+M28/60+int(N28)/3600) -> -43.910833
A29: 5LN29 | B29: S19 50 35.07 | C29: W043 27 41.30 | D29: 28 | E29: =concatenate(RIGHT($G29,2),text($H29+$J29,"00.000"),LEFT($G29,1)) -> 1950.585S | F29: =concatenate(RIGHT($L29,3),text($M29+$O29,"00.000"),LEFT($L29,1)) -> 04327.688W | G29: =IFERROR(__xludf.DUMMYFUNCTION("SPLIT($B29,"" "")"),"S19") -> S19 | H29: =IFERROR(__xludf.DUMMYFUNCTION("""COMPUTED_VALUE"""),50.0) -> 50 | I29: =IFERROR(__xludf.DUMMYFUNCTION("""COMPUTED_VALUE"""),35.07) -> 35.07 | J29: =text(ROUND(I29/60,3),"0.000") -> 0.585 | L29: =IFERROR(__xludf.DUMMYFUNCTION("SPLIT($C29,"" "")"),"W043") -> W043 | M29: =IFERROR(__xludf.DUMMYFUNCTION("""COMPUTED_VALUE"""),27.0) -> 27 | N29: =IFERROR(__xludf.DUMMYFUNCTION("""COMPUTED_VALUE"""),41.3) -> 41.3 | O29: =text(round(N29/60,3),"0.000") -> 0.688 | Q29: =-1*(RIGHT(G29,2)+H29/60+INT(I29)/3600) -> -19.843056 | R29: =-1*(RIGHT(L29,3)+M29/60+int(N29)/3600) -> -43.461389
A30: 5LN30 | B30: S19 10 52.50 | C30: W044 00 05.82 | D30: 29 | E30: =concatenate(RIGHT($G30,2),text($H30+$J30,"00.000"),LEFT($G30,1)) -> 1910.875S | F30: =concatenate(RIGHT($L30,3),text($M30+$O30,"00.000"),LEFT($L30,1)) -> 04400.097W | G30: =IFERROR(__xludf.DUMMYFUNCTION("SPLIT($B30,"" "")"),"S19") -> S19 | H30: =IFERROR(__xludf.DUMMYFUNCTION("""COMPUTED_VALUE"""),10.0) -> 10 | I30: =IFERROR(__xludf.DUMMYFUNCTION("""COMPUTED_VALUE"""),52.5) -> 52.5 | J30: =text(ROUND(I30/60,3),"0.000") -> 0.875 | L30: =IFERROR(__xludf.DUMMYFUNCTION("SPLIT($C30,"" "")"),"W044") -> W044 | M30: =IFERROR(__xludf.DUMMYFUNCTION("""COMPUTED_VALUE"""),0.0) -> 0 | N30: =IFERROR(__xludf.DUMMYFUNCTION("""COMPUTED_VALUE"""),5.82) -> 5.82 | O30: =text(round(N30/60,3),"0.000") -> 0.097 | Q30: =-1*(RIGHT(G30,2)+H30/60+INT(I30)/3600) -> -19.181111 | R30: =-1*(RIGHT(L30,3)+M30/60+int(N30)/3600) -> -44.001389
A31: 5LN32 | B31: S19 49 22.67 | C31: W044 17 21.31 | D31: 30 | E31: =concatenate(RIGHT($G31,2),text($H31+$J31,"00.000"),LEFT($G31,1)) -> 1949.378S | F31: =concatenate(RIGHT($L31,3),text($M31+$O31,"00.000"),LEFT($L31,1)) -> 04417.355W | G31: =IFERROR(__xludf.DUMMYFUNCTION("SPLIT($B31,"" "")"),"S19") -> S19 | H31: =IFERROR(__xludf.DUMMYFUNCTION("""COMPUTED_VALUE"""),49.0) -> 49 | I31: =IFERROR(__xludf.DUMMYFUNCTION("""COMPUTED_VALUE"""),22.67) -> 22.67 | J31: =text(ROUND(I31/60,3),"0.000") -> 0.378 | L31: =IFERROR(__xludf.DUMMYFUNCTION("SPLIT($C31,"" "")"),"W044") -> W044 | M31: =IFERROR(__xludf.DUMMYFUNCTION("""COMPUTED_VALUE"""),17.0) -> 17 | N31: =IFERROR(__xludf.DUMMYFUNCTION("""COMPUTED_VALUE"""),21.31) -> 21.31 | O31: =text(round(N31/60,3),"0.000") -> 0.355 | Q31: =-1*(RIGHT(G31,2)+H31/60+INT(I31)/3600) -> -19.822778 | R31: =-1*(RIGHT(L31,3)+M31/60+int(N31)/3600) -> -44.289167
A32: 5LN33 | B32: S19 07 33.90 | C32: W044 36 40.78 | D32: 31 | E32: =concatenate(RIGHT($G32,2),text($H32+$J32,"00.000"),LEFT($G32,1)) -> 1907.565S | F32: =concatenate(RIGHT($L32,3),text($M32+$O32,"00.000"),LEFT($L32,1)) -> 04436.680W | G32: =IFERROR(__xludf.DUMMYFUNCTION("SPLIT($B32,"" "")"),"S19") -> S19 | H32: =IFERROR(__xludf.DUMMYFUNCTION("""COMPUTED_VALUE"""),7.0) -> 7 | I32: =IFERROR(__xludf.DUMMYFUNCTION("""COMPUTED_VALUE"""),33.9) -> 33.9 | J32: =text(ROUND(I32/60,3),"0.000") -> 0.565 | L32: =IFERROR(__xludf.DUMMYFUNCTION("SPLIT($C32,"" "")"),"W044") -> W044 | M32: =IFERROR(__xludf.DUMMYFUNCTION("""COMPUTED_VALUE"""),36.0) -> 36 | N32: =IFERROR(__xludf.DUMMYFUNCTION("""COMPUTED_VALUE"""),40.78) -> 40.78 | O32: =text(round(N32/60,3),"0.000") -> 0.680 | Q32: =-1*(RIGHT(G32,2)+H32/60+INT(I32)/3600) -> -19.125833 | R32: =-1*(RIGHT(L32,3)+M32/60+int(N32)/3600) -> -44.611111
A33: 5LN34 | B33: S20 03 44.71 | C33: W043 39 25.32 | D33: 32 | E33: =concatenate(RIGHT($G33,2),text($H33+$J33,"00.000"),LEFT($G33,1)) -> 2003.745S | F33: =concatenate(RIGHT($L33,3),text($M33+$O33,"00.000"),LEFT($L33,1)) -> 04339.422W | G33: =IFERROR(__xludf.DUMMYFUNCTION("SPLIT($B33,"" "")"),"S20") -> S20 | H33: =IFERROR(__xludf.DUMMYFUNCTION("""COMPUTED_VALUE"""),3.0) -> 3 | I33: =IFERROR(__xludf.DUMMYFUNCTION("""COMPUTED_VALUE"""),44.71) -> 44.71 | J33: =text(ROUND(I33/60,3),"0.000") -> 0.745 | L33: =IFERROR(__xludf.DUMMYFUNCTION("SPLIT($C33,"" "")"),"W043") -> W043 | M33: =IFERROR(__xludf.DUMMYFUNCTION("""COMPUTED_VALUE"""),39.0) -> 39 | N33: =IFERROR(__xludf.DUMMYFUNCTION("""COMPUTED_VALUE"""),25.32) -> 25.32 | O33: =text(round(N33/60,3),"0.000") -> 0.422 | Q33: =-1*(RIGHT(G33,2)+H33/60+INT(I33)/3600) -> -20.062222 | R33: =-1*(RIGHT(L33,3)+M33/60+int(N33)/3600) -> -43.656944
A34: 5LN35 | B34: S19 26 07.83 | C34: W044 43 40.77 | D34: 33 | E34: =concatenate(RIGHT($G34,2),text($H34+$J34,"00.000"),LEFT($G34,1)) -> 1926.131S | F34: =concatenate(RIGHT($L34,3),text($M34+$O34,"00.000"),LEFT($L34,1)) -> 04443.680W | G34: =IFERROR(__xludf.DUMMYFUNCTION("SPLIT($B34,"" "")"),"S19") -> S19 | H34: =IFERROR(__xludf.DUMMYFUNCTION("""COMPUTED_VALUE"""),26.0) -> 26 | I34: =IFERROR(__xludf.DUMMYFUNCTION("""COMPUTED_VALUE"""),7.83) -> 7.83 | J34: =text(ROUND(I34/60,3),"0.000") -> 0.131 | L34: =IFERROR(__xludf.DUMMYFUNCTION("SPLIT($C34,"" "")"),"W044") -> W044 | M34: =IFERROR(__xludf.DUMMYFUNCTION("""COMPUTED_VALUE"""),43.0) -> 43 | N34: =IFERROR(__xludf.DUMMYFUNCTION("""COMPUTED_VALUE"""),40.77) -> 40.77 | O34: =text(round(N34/60,3),"0.000") -> 0.680 | Q34: =-1*(RIGHT(G34,2)+H34/60+INT(I34)/3600) -> -19.435278 | R34: =-1*(RIGHT(L34,3)+M34/60+int(N34)/3600) -> -44.727778
A35: 5LN36 | B35: S20 08 55.74 | C35: W043 37 02.86 | D35: 34 | E35: =concatenate(RIGHT($G35,2),text($H35+$J35,"00.000"),LEFT($G35,1)) -> 2008.929S | F35: =concatenate(RIGHT($L35,3),text($M35+$O35,"00.000"),LEFT($L35,1)) -> 04337.048W | G35: =IFERROR(__xludf.DUMMYFUNCTION("SPLIT($B35,"" "")"),"S20") -> S20 | H35: =IFERROR(__xludf.DUMMYFUNCTION("""COMPUTED_VALUE"""),8.0) -> 8 | I35: =IFERROR(__xludf.DUMMYFUNCTION("""COMPUTED_VALUE"""),55.74) -> 55.74 | J35: =text(ROUND(I35/60,3),"0.000") -> 0.929 | L35: =IFERROR(__xludf.DUMMYFUNCTION("SPLIT($C35,"" "")"),"W043") -> W043 | M35: =IFERROR(__xludf.DUMMYFUNCTION("""COMPUTED_VALUE"""),37.0) -> 37 | N35: =IFERROR(__xludf.DUMMYFUNCTION("""COMPUTED_VALUE"""),2.86) -> 2.86 | O35: =text(round(N35/60,3),"0.000") -> 0.048 | Q35: =-1*(RIGHT(G35,2)+H35/60+INT(I35)/3600) -> -20.148611 | R35: =-1*(RIGHT(L35,3)+M35/60+int(N35)/3600) -> -43.617222
A36: 5LN37 | B36: S18 55 22.21 | C36: W043 34 59.91 | D36: 35 | E36: =concatenate(RIGHT($G36,2),text($H36+$J36,"00.000"),LEFT($G36,1)) -> 1855.370S | F36: =concatenate(RIGHT($L36,3),text($M36+$O36,"00.000"),LEFT($L36,1)) -> 04334.999W | G36: =IFERROR(__xludf.DUMMYFUNCTION("SPLIT($B36,"" "")"),"S18") -> S18 | H36: =IFERROR(__xludf.DUMMYFUNCTION("""COMPUTED_VALUE"""),55.0) -> 55 | I36: =IFERROR(__xludf.DUMMYFUNCTION("""COMPUTED_VALUE"""),22.21) -> 22.21 | J36: =text(ROUND(I36/60,3),"0.000") -> 0.370 | L36: =IFERROR(__xludf.DUMMYFUNCTION("SPLIT($C36,"" "")"),"W043") -> W043 | M36: =IFERROR(__xludf.DUMMYFUNCTION("""COMPUTED_VALUE"""),34.0) -> 34 | N36: =IFERROR(__xludf.DUMMYFUNCTION("""COMPUTED_VALUE"""),59.91) -> 59.91 | O36: =text(round(N36/60,3),"0.000") -> 0.999 | Q36: =-1*(RIGHT(G36,2)+H36/60+INT(I36)/3600) -> -18.922778 | R36: =-1*(RIGHT(L36,3)+M36/60+int(N36)/3600) -> -43.583056
A37: 5LN38 | B37: S19 54 26.57 | C37: W044 08 33.09 | D37: 36 | E37: =concatenate(RIGHT($G37,2),text($H37+$J37,"00.000"),LEFT($G37,1)) -> 1954.443S | F37: =concatenate(RIGHT($L37,3),text($M37+$O37,"00.000"),LEFT($L37,1)) -> 04408.552W | G37: =IFERROR(__xludf.DUMMYFUNCTION("SPLIT($B37,"" "")"),"S19") -> S19 | H37: =IFERROR(__xludf.DUMMYFUNCTION("""COMPUTED_VALUE"""),54.0) -> 54 | I37: =IFERROR(__xludf.DUMMYFUNCTION("""COMPUTED_VALUE"""),26.57) -> 26.57 | J37: =text(ROUND(I37/60,3),"0.000") -> 0.443 | L37: =IFERROR(__xludf.DUMMYFUNCTION("SPLIT($C37,"" "")"),"W044") -> W044 | M37: =IFERROR(__xludf.DUMMYFUNCTION("""COMPUTED_VALUE"""),8.0) -> 8 | N37: =IFERROR(__xludf.DUMMYFUNCTION("""COMPUTED_VALUE"""),33.09) -> 33.09 | O37: =text(round(N37/60,3),"0.000") -> 0.552 | Q37: =-1*(RIGHT(G37,2)+H37/60+INT(I37)/3600) -> -19.907222 | R37: =-1*(RIGHT(L37,3)+M37/60+int(N37)/3600) -> -44.1425
A38: 5LN39 | B38: S19 48 49.65 | C38: W044 14 15.36 | D38: 37 | E38: =concatenate(RIGHT($G38,2),text($H38+$J38,"00.000"),LEFT($G38,1)) -> 1948.828S | F38: =concatenate(RIGHT($L38,3),text($M38+$O38,"00.000"),LEFT($L38,1)) -> 04414.256W | G38: =IFERROR(__xludf.DUMMYFUNCTION("SPLIT($B38,"" "")"),"S19") -> S19 | H38: =IFERROR(__xludf.DUMMYFUNCTION("""COMPUTED_VALUE"""),48.0) -> 48 | I38: =IFERROR(__xludf.DUMMYFUNCTION("""COMPUTED_VALUE"""),49.65) -> 49.65 | J38: =text(ROUND(I38/60,3),"0.000") -> 0.828 | L38: =IFERROR(__xludf.DUMMYFUNCTION("SPLIT($C38,"" "")"),"W044") -> W044 | M38: =IFERROR(__xludf.DUMMYFUNCTION("""COMPUTED_VALUE"""),14.0) -> 14 | N38: =IFERROR(__xludf.DUMMYFUNCTION("""COMPUTED_VALUE"""),15.36) -> 15.36 | O38: =text(round(N38/60,3),"0.000") -> 0.256 | Q38: =-1*(RIGHT(G38,2)+H38/60+INT(I38)/3600) -> -19.813611 | R38: =-1*(RIGHT(L38,3)+M38/60+int(N38)/3600) -> -44.2375
A39: 5LN40 | B39: S20 11 30.50 | C39: W044 33 19.61 | D39: 38 | E39: =concatenate(RIGHT($G39,2),text($H39+$J39,"00.000"),LEFT($G39,1)) -> 2011.508S | F39: =concatenate(RIGHT($L39,3),text($M39+$O39,"00.000"),LEFT($L39,1)) -> 04433.327W | G39: =IFERROR(__xludf.DUMMYFUNCTION("SPLIT($B39,"" "")"),"S20") -> S20 | H39: =IFERROR(__xludf.DUMMYFUNCTION("""COMPUTED_VALUE"""),11.0) -> 11 | I39: =IFERROR(__xludf.DUMMYFUNCTION("""COMPUTED_VALUE"""),30.5) -> 30.5 | J39: =text(ROUND(I39/60,3),"0.000") -> 0.508 | L39: =IFERROR(__xludf.DUMMYFUNCTION("SPLIT($C39,"" "")"),"W044") -> W044 | M39: =IFERROR(__xludf.DUMMYFUNCTION("""COMPUTED_VALUE"""),33.0) -> 33 | N39: =IFERROR(__xludf.DUMMYFUNCTION("""COMPUTED_VALUE"""),19.61) -> 19.61 | O39: =text(round(N39/60,3),"0.000") -> 0.327 | Q39: =-1*(RIGHT(G39,2)+H39/60+INT(I39)/3600) -> -20.191667 | R39: =-1*(RIGHT(L39,3)+M39/60+int(N39)/3600) -> -44.555278
A40: 5LN55 | B40: S20 01 27.10 | C40: W043 46 14.42 | D40: 39 | E40: =concatenate(RIGHT($G40,2),text($H40+$J40,"00.000"),LEFT($G40,1)) -> 2001.452S | F40: =concatenate(RIGHT($L40,3),text($M40+$O40,"00.000"),LEFT($L40,1)) -> 04346.240W | G40: =IFERROR(__xludf.DUMMYFUNCTION("SPLIT($B40,"" "")"),"S20") -> S20 | H40: =IFERROR(__xludf.DUMMYFUNCTION("""COMPUTED_VALUE"""),1.0) -> 1 | I40: =IFERROR(__xludf.DUMMYFUNCTION("""COMPUTED_VALUE"""),27.1) -> 27.1 | J40: =text(ROUND(I40/60,3),"0.000") -> 0.452 | L40: =IFERROR(__xludf.DUMMYFUNCTION("SPLIT($C40,"" "")"),"W043") -> W043 | M40: =IFERROR(__xludf.DUMMYFUNCTION("""COMPUTED_VALUE"""),46.0) -> 46 | N40: =IFERROR(__xludf.DUMMYFUNCTION("""COMPUTED_VALUE"""),14.42) -> 14.42 | O40: =text(round(N40/60,3),"0.000") -> 0.240 | Q40: =-1*(RIGHT(G40,2)+H40/60+INT(I40)/3600) -> -20.024167 | R40: =-1*(RIGHT(L40,3)+M40/60+int(N40)/3600) -> -43.770556
...
